Traceback (most recent call last):
  File "/usr/share/miniconda3/envs/exec-book-template/lib/python3.7/site-packages/jupyter_cache/executors/utils.py", line 56, in single_nb_execution
    record_timing=False,
  File "/usr/share/miniconda3/envs/exec-book-template/lib/python3.7/site-packages/nbclient/client.py", line 1204, in execute
    return NotebookClient(nb=nb, resources=resources, km=km, **kwargs).execute()
  File "/usr/share/miniconda3/envs/exec-book-template/lib/python3.7/site-packages/nbclient/util.py", line 84, in wrapped
    return just_run(coro(*args, **kwargs))
  File "/usr/share/miniconda3/envs/exec-book-template/lib/python3.7/site-packages/nbclient/util.py", line 62, in just_run
    return loop.run_until_complete(coro)
  File "/usr/share/miniconda3/envs/exec-book-template/lib/python3.7/asyncio/base_events.py", line 587, in run_until_complete
    return future.result()
  File "/usr/share/miniconda3/envs/exec-book-template/lib/python3.7/site-packages/nbclient/client.py", line 664, in async_execute
    cell, index, execution_count=self.code_cells_executed + 1
  File "/usr/share/miniconda3/envs/exec-book-template/lib/python3.7/site-packages/nbclient/client.py", line 965, in async_execute_cell
    await self._check_raise_for_error(cell, cell_index, exec_reply)
  File "/usr/share/miniconda3/envs/exec-book-template/lib/python3.7/site-packages/nbclient/client.py", line 862, in _check_raise_for_error
    raise CellExecutionError.from_cell_and_msg(cell, exec_reply_content)
nbclient.exceptions.CellExecutionError: An error occurred while executing the following cell:
------------------
import nibabel as nib
from nilearn.plotting import view_img

zmap = nib.load('data/unthresh_Z.nii.gz')
view_img(zmap, threshold=2.8)
------------------

[0;31m---------------------------------------------------------------------------[0m
[0;31mFileNotFoundError[0m                         Traceback (most recent call last)
[0;32m/usr/share/miniconda3/envs/exec-book-template/lib/python3.7/site-packages/nibabel/loadsave.py[0m in [0;36mload[0;34m(filename, **kwargs)[0m
[1;32m     41[0m     [0;32mtry[0m[0;34m:[0m[0;34m[0m[0;34m[0m[0m
[0;32m---> 42[0;31m         [0mstat_result[0m [0;34m=[0m [0mos[0m[0;34m.[0m[0mstat[0m[0;34m([0m[0mfilename[0m[0;34m)[0m[0;34m[0m[0;34m[0m[0m
[0m[1;32m     43[0m     [0;32mexcept[0m [0mOSError[0m[0;34m:[0m[0;34m[0m[0;34m[0m[0m

[0;31mFileNotFoundError[0m: [Errno 2] No such file or directory: 'data/unthresh_Z.nii.gz'

During handling of the above exception, another exception occurred:

[0;31mFileNotFoundError[0m                         Traceback (most recent call last)
[0;32m/tmp/ipykernel_6186/3597648802.py[0m in [0;36m<module>[0;34m[0m
[1;32m      2[0m [0;32mfrom[0m [0mnilearn[0m[0;34m.[0m[0mplotting[0m [0;32mimport[0m [0mview_img[0m[0;34m[0m[0;34m[0m[0m
[1;32m      3[0m [0;34m[0m[0m
[0;32m----> 4[0;31m [0mzmap[0m [0;34m=[0m [0mnib[0m[0;34m.[0m[0mload[0m[0;34m([0m[0;34m'data/unthresh_Z.nii.gz'[0m[0;34m)[0m[0;34m[0m[0;34m[0m[0m
[0m[1;32m      5[0m [0mview_img[0m[0;34m([0m[0mzmap[0m[0;34m,[0m [0mthreshold[0m[0;34m=[0m[0;36m2.8[0m[0;34m)[0m[0;34m[0m[0;34m[0m[0m

[0;32m/usr/share/miniconda3/envs/exec-book-template/lib/python3.7/site-packages/nibabel/loadsave.py[0m in [0;36mload[0;34m(filename, **kwargs)[0m
[1;32m     42[0m         [0mstat_result[0m [0;34m=[0m [0mos[0m[0;34m.[0m[0mstat[0m[0;34m([0m[0mfilename[0m[0;34m)[0m[0;34m[0m[0;34m[0m[0m
[1;32m     43[0m     [0;32mexcept[0m [0mOSError[0m[0;34m:[0m[0;34m[0m[0;34m[0m[0m
[0;32m---> 44[0;31m         [0;32mraise[0m [0mFileNotFoundError[0m[0;34m([0m[0;34mf"No such file or no access: '{filename}'"[0m[0;34m)[0m[0;34m[0m[0;34m[0m[0m
[0m[1;32m     45[0m     [0;32mif[0m [0mstat_result[0m[0;34m.[0m[0mst_size[0m [0;34m<=[0m [0;36m0[0m[0;34m:[0m[0;34m[0m[0;34m[0m[0m
[1;32m     46[0m         [0;32mraise[0m [0mImageFileError[0m[0;34m([0m[0;34mf"Empty file: '{filename}'"[0m[0;34m)[0m[0;34m[0m[0;34m[0m[0m

[0;31mFileNotFoundError[0m: No such file or no access: 'data/unthresh_Z.nii.gz'
FileNotFoundError: No such file or no access: 'data/unthresh_Z.nii.gz'

